E:\Code\CartDB\CartScraper> python .\cartscraper.py
ERROR WITH: http://bootgod.dyndns.org:7777/profile.php?id=2416
(<class 'requests.exceptions.ConnectionError'>, ConnectionError(MaxRetryError("HTTPConnectionPool(host='bootgod.dyndns.org', port=7777): Max retries exceeded with url: /profile.php?id=2416 (Caused by NewConnectionError('<urllib3.connection.HTTPConnection object at 0x0000017C0D9BEC70>: Failed to establish a new connection: [WinError 10060] A connection attempt failed because the connected party did not properly respond after a period of time, or established connection failed because connected host has failed to respond'))")), <traceback object at 0x0000017C0DC84EC0>)
  File ".\cartscraper.py", line 68, in main
    page = requests.get(BASE_URL + URL + str(i))
  File "C:\Python38\lib\site-packages\requests\api.py", line 76, in get
    return request('get', url, params=params, **kwargs)
  File "C:\Python38\lib\site-packages\requests\api.py", line 61, in request
    return session.request(method=method, url=url, **kwargs)
  File "C:\Python38\lib\site-packages\requests\sessions.py", line 542, in request
    resp = self.send(prep, **send_kwargs)
  File "C:\Python38\lib\site-packages\requests\sessions.py", line 655, in send
    r = adapter.send(request, **kwargs)
  File "C:\Python38\lib\site-packages\requests\adapters.py", line 516, in send
    raise ConnectionError(e, request=request)

ERROR WITH: http://bootgod.dyndns.org:7777/profile.php?id=4731
(<class 'IndexError'>, IndexError('list index out of range'), <traceback object at 0x0000017C0F873BC0>)
  File ".\cartscraper.py", line 233, in main
    cartridgechip.partnumber = str(chip_info_table.find_all("tr")[j].find_all("td")[2].contents[0]).strip()

Errors: 2
Unavailable: 400